Workbook

Sheet Overview
A1: NORAM Account Executive Onboarding
A2: From Day 1 to first Propose: a 90-day path built for selling payments at Checkout.com
A3: Jasmine Jancsik, Lead Enablement, US · v1 draft, October 2026
A5: Sessions mapped | B5: =COUNTA(Inventory!C4:C500)
A6: Ready today | B6: =COUNTIF(Inventory!H4:H500,"Ready")
A7: Need refresh | B7: =COUNTIF(Inventory!H4:H500,"Refresh")
A8: To build | B8: =COUNTIF(Inventory!H4:H500,"Build")
A10: Build/refresh items done | B10: =COUNTIF('Build Backlog'!H4:H500,"Done")
A12: Phase | B12: Days | C12: Theme | D12: Goal | E12: Target selling time
A13: Pre-board | B13: Before Day 1 | C13: Arrive ready | D13: Day 1 is about people, not passwords. Tools, plan and buddy are in place before the AE walks in. | E13: 0%
A14: Land | B14: Days 1–14 | C14: Belong & orient | D14: Understand how Checkout sells, who's who, the territory and the rules of engagement. Payments is told as a story first, then studied as a curriculum. | E14: ≤10%
A15: Learn | B15: Days 15–30 | C15: Payments & product fluency | D15: Explain all five pillars in a merchant's language, see each pillar in live deals, and start call reviews and account planning. | E15: 20%
A16: Practice | B16: Days 31–60 | C16: Verticals, process & discovery | D16: Go deep on NORAM verticals and the deal machine (deal desk, underwriting, partners), then prove discovery skills in the Day 60 Explore stack. | E16: 50%
A17: Perform | B17: Days 61–90 | C17: Price, propose & close | D17: Price a deal, build a business case and present a tailored Checkout pitch. Graduation is the Day 90 Pitch Deck Certification. | E17: 70%
A18: Everboard | B18: Day 90+ | C18: Keep growing | D18: Recurring skills sessions, call clinics and yearly recertification keep tenured AEs sharp. | E18: 90%+
A20: Milestone | B20: Day | C20: What | D20: Pass mark
A21: Day 30 Checkpoint | B21: 30 | C21: Elevator pitch sign-off + five-pillar knowledge check | D21: Pitch approved by manager · ≥ 80% on the pillar knowledge check
A22: Explore Call Certification | B22: 60 | C22: Live simulated Explore call with a payments persona, scored on a 7-part rubric | D22: ≥ 80% overall and no section below 3/5
A23: Pitch Deck Certification | B23: 90 | C23: Tailored pitch deck for a real territory account, presented to a panel | D23: ≥ 80% overall and no section below 3/5

Sheet Inventory
A1: Every AE onboarding session: what exists today (Ready), what needs updating (Refresh) and what's missing (Build).
A3: Phase | B3: Week | C3: Session | D3: Category | E3: Format | F3: Hours | G3: Owner | H3: Status | I3: Stack | J3: What needs to happen / notes | K3: Source
A4: Pre-board (Before Day 1) | B4: 0 | C4: Welcome pack, 90-day plan & personal tracker issued | D4: Foundations | E4: Self-paced | F4: 0.5 | G4: Enablement | H4: Build | J4: Send the personal tracker (Karlie Chen format) and this 90-day map before Day 1 so the new hire arrives knowing the path. | K4: Karlie Tracker
A5: Pre-board (Before Day 1) | B5: 0 | C5: Tool access pre-provisioned (Salesforce, Clari, Apollo, LinkedIn Sales Nav, Highspot, Glean) | D5: Tools & Process | E5: Self-paced | F5: 0 | G5: Enablement + IT | H5: Refresh | J5: Today this takes a Day 1 session. Request access at offer-accept so Day 1 can go to people and context. | K5: Q4 Plan
A6: Pre-board (Before Day 1) | B6: 0 | C6: Buddy assigned + manager welcome call | D6: People & Network | E6: Live | F6: 0.5 | G6: Line manager | H6: Refresh | J6: Buddies are used informally (elevator pitch, role plays). Formalise it with a one-page buddy guide and a weekly 30-minute slot. | K6: Karlie Tracker
A7: Land (Days 1–14) | B7: 1 | C7: IT, People & Benefits inductions | D7: Foundations | E7: Live | F7: 3 | G7: People Team | H7: Ready | K7: Q4 Plan
A8: Land (Days 1–14) | B8: 1 | C8: Your onboarding plan: the 30/60/90 kickoff | D8: Foundations | E8: Live | F8: 0.5 | G8: Enablement | H8: Ready | K8: Q4 Plan
A9: Land (Days 1–14) | B9: 1 | C9: Intro to Checkout's Revenue Org (Global + NORAM) | D9: Foundations | E9: Live | F9: 1.5 | G9: Michel Tornabene | H9: Ready | K9: Karlie Tracker
A10: Land (Days 1–14) | B10: 1 | C10: Mandatory compliance training (Nova) | D10: Foundations | E10: Self-paced | F10: 3 | G10: New hire | H10: Ready | K10: Q4 Plan
A11: Land (Days 1–14) | B11: 1 | C11: Payments at Checkout in 60 minutes | D11: Payments & Product | E11: Live | F11: 1 | G11: Enablement + Solutions Engineering | H11: Build | J11: A story-led primer: the life of a card transaction, where Checkout earns, and why merchants switch. It replaces the Day 2 deep dive into Payments Academy and gives context before the curriculum starts. | K11: New
A12: Land (Days 1–14) | B12: 1 | C12: Sales Tools & Chrome Extensions | D12: Tools & Process | E12: Live | F12: 1 | G12: J.J. Henry | H12: Ready | K12: Karlie Tracker
A13: Land (Days 1–14) | B13: 1 | C13: Finding answers: Highspot, Confluence & Glean | D13: Tools & Process | E13: Live | F13: 1 | G13: Enablement | H13: Refresh | J13: Update for the Highspot→Drive transition and Glean adoption (charter priority 3). | K13: Q4 Plan
A14: Land (Days 1–14) | B14: 1 | C14: Office hours with the NORAM GM | D14: People & Network | E14: Live | F14: 0.5 | G14: Zack Levine | H14: Ready | K14: Q4 Plan
A15: Land (Days 1–14) | B15: 1 | C15: RevWay 0–1: Intro to Revenue Way & Buyer Psychology | D15: Sales Skills | E15: Self-paced | F15: 2.5 | G15: Self-directed | H15: Ready | K15: Q4 Plan
A16: Land (Days 1–14) | B16: 1 | C16: Meet your pod + buddy coffee | D16: People & Network | E16: Practice | F16: 1 | G16: Pod leader | H16: Ready | K16: Q4 Plan
A17: Land (Days 1–14) | B17: 2 | C17: Buyer personas in payments (Head of Payments, CFO, CPO, Eng) | D17: Sales Skills | E17: Live | F17: 1 | G17: J.J. Henry | H17: Ready | K17: Karlie Tracker
A18: Land (Days 1–14) | B18: 2 | C18: Competitive Landscape | D18: Payments & Product | E18: Live | F18: 1 | G18: Michel Tornabene | H18: Ready | K18: Q4 Plan
A19: Land (Days 1–14) | B19: 2 | C19: Territory planning (STP), Rules of Engagement & Incentive Ratings | D19: Tools & Process | E19: Live | F19: 1 | G19: Francesco Falcone | H19: Ready | J19: Must be live and finished by the end of Week 2. Francesco asked for this ASAP, early Week 3 at the latest. | K19: Q4 Plan
A20: Land (Days 1–14) | B20: 2 | C20: Salesforce, Clari & pipeline hygiene | D20: Tools & Process | E20: Live | F20: 1 | G20: Francesco Falcone | H20: Ready | K20: Q4 Plan
A21: Land (Days 1–14) | B21: 2 | C21: AI in Commercial | D21: Tools & Process | E21: Live | F21: 1 | G21: Molly McKenna | H21: Ready | K21: Q4 Plan
A22: Land (Days 1–14) | B22: 2 | C22: Meet the team: Sales, AM, Financial Partnerships, Partnerships, SE, RevOps | D22: People & Network | E22: Live | F22: 3 | G22: Team leads | H22: Ready | J22: Six 30-minute intros, using the prioritised Who-to-Meet list from the NY repository. | K22: NY Repository
A23: Land (Days 1–14) | B23: 2 | C23: Payments Academy: Foundations modules 1–5 | D23: Payments & Product | E23: Self-paced | F23: 2.5 | G23: Self-directed | H23: Refresh | J23: Moved from Day 2 to Week 2 and paced at about 30 minutes a day, after the 60-minute primer, with a Friday live debrief. | K23: Q4 Plan
A24: Land (Days 1–14) | B24: 2 | C24: RevWay 2–3: DEPTH Selling & Managing Pipeline | D24: Sales Skills | E24: Self-paced | F24: 2.5 | G24: Self-directed | H24: Ready | K24: Q4 Plan
A25: Land (Days 1–14) | B25: 2 | C25: Friday knowledge check (Kahoot, pod leads join), runs weekly | D25: Payments & Product | E25: Practice | F25: 0.5 | G25: Enablement + pod leads | H25: Ready | K25: Q4 Plan
A26: Learn (Days 15–30) | B26: 3 | C26: Payments Academy: Foundations 6–10 + live debrief | D26: Payments & Product | E26: Self-paced | F26: 3 | G26: Enablement | H26: Refresh | J26: Finish the Foundations here, not in Week 1. The debrief turns the modules into talk-tracks. | K26: Q4 Plan
A27: Learn (Days 15–30) | B27: 3 | C27: Product Foundations: Connect & Move | D27: Payments & Product | E27: Self-paced | F27: 2 | G27: Self-directed | H27: Ready | K27: Karlie Tracker
A28: Learn (Days 15–30) | B28: 3 | C28: Pillars in live deals: Connect & Move (30 min each) | D28: Payments & Product | E28: Live | F28: 1 | G28: Pod leads | H28: Refresh | J28: Replace the generic 'sales perspective' sessions with 30-minute walk-throughs of live deals, built on a vertical use case (Francesco's feedback). | K28: Q4 Plan
A29: Learn (Days 15–30) | B29: 3 | C29: International Outlook: acquiring set-ups & cross-border | D29: Payments & Product | E29: Live | F29: 0.75 | G29: Michel Tornabene | H29: Ready | K29: Q4 Plan
A30: Learn (Days 15–30) | B30: 3 | C30: Commercial Risk | D30: Payments & Product | E30: Live | F30: 0.5 | G30: Michel Tornabene | H30: Ready | K30: Karlie Tracker
A31: Learn (Days 15–30) | B31: 3 | C31: Intro to NORAM verticals & where we win | D31: Payments & Product | E31: Live | F31: 0.75 | G31: Francesco Falcone | H31: Ready | J31: Pair this with the North America Vertical List in the NY repository. | K31: Q4 Plan
A32: Learn (Days 15–30) | B32: 3 | C32: Weekly call-review hour begins (Clari gametapes) | D32: Sales Skills | E32: Practice | F32: 1 | G32: Jim Cho + Francesco Falcone | H32: Ready | J32: Starts in Week 3, not Week 1, then runs weekly (Francesco's feedback). | K32: Q4 Plan
A33: Learn (Days 15–30) | B33: 3 | C33: Outreach lab: openers, email personalisation & gatekeepers | D33: Sales Skills | E33: Live | F33: 2 | G33: J.J. Henry | H33: Ready | K33: Karlie Tracker
A34: Learn (Days 15–30) | B34: 4 | C34: Product Foundations: Protect, Boost & Manage | D34: Payments & Product | E34: Self-paced | F34: 2.5 | G34: Self-directed | H34: Ready | K34: Karlie Tracker
A35: Learn (Days 15–30) | B35: 4 | C35: Pillars in live deals: Protect, Boost & Manage | D35: Payments & Product | E35: Live | F35: 1 | G35: Pod leads | H35: Refresh | J35: Same 30-minute live-deal format as Week 3. | K35: Q4 Plan
A36: Learn (Days 15–30) | B36: 4 | C36: Payment Performance AMA (Boost) | D36: Payments & Product | E36: Live | F36: 1 | G36: Daniel Linder | H36: Ready | J36: Focus on Boost, Daniel's pillar. | K36: Q4 Plan
A37: Learn (Days 15–30) | B37: 4 | C37: Account list review: your Top 70 | D37: Sales Skills | E37: Practice | F37: 1 | G37: Line manager | H37: Ready | K37: Karlie Tracker
A38: Learn (Days 15–30) | B38: 4 | C38: RevWay 4–5: Discovery & Explore phases | D38: Sales Skills | E38: Self-paced | F38: 2.5 | G38: Self-directed | H38: Ready | K38: Q4 Plan
A39: Learn (Days 15–30) | B39: 4 | C39: Cold-call role play | D39: Sales Skills | E39: Practice | F39: 0.5 | G39: J.J. Henry | H39: Ready | K39: Karlie Tracker
A40: Learn (Days 15–30) | B40: 4 | C40: Day 30 Checkpoint: elevator pitch + five-pillar knowledge check | D40: Certification | E40: Certification | F40: 1 | G40: Line manager + Enablement | H40: Refresh | I40: Day 30 | J40: Combine today's elevator-pitch reviews and pillar Kahoots into one recorded gate. | K40: Karlie Tracker
A41: Practice (Days 31–60) | B41: 5 | C41: Vertical deep dives: Digital Content and Ecommerce | D41: Payments & Product | E41: Live | F41: 1.5 | G41: Jules Gay / Katie Wile | H41: Ready | K41: Q4 Plan
...

Sheet Build Backlog
A1: P1 = needed for the next cohort (certifications, Day 60/90 stacks, Day 1 payments primer). Update Progress as content is built.
A3: Priority | B3: Type | C3: Session | D3: Phase | E3: Week | F3: Proposed owner | G3: Target date | H3: Progress | I3: Content link | J3: Brief
A4: P1 | B4: Build | C4: Payments at Checkout in 60 minutes | D4: Land (Days 1–14) | E4: 1 | F4: Enablement + Solutions Engineering | H4: Not started | J4: A story-led primer: the life of a card transaction, where Checkout earns, and why merchants switch. It replaces the Day 2 deep dive into Payments Academy and gives context before the curriculum starts.
A5: P1 | B5: Build | C5: Explore Call Masterclass: running discovery the Checkout way | D5: Practice (Days 31–60) | E5: 9 | F5: Enablement + top AE | H5: Not started | J5: Live, AE-specific application of RevWay 5–6: agenda, upfront contract, DEPTH funnel and summarise-to-commit.
A6: P1 | B6: Build | C6: Payments discovery question bank & value hypothesis | D6: Practice (Days 31–60) | E6: 9 | F6: Enablement + Solutions Engineering | H6: Not started | J6: Questions by persona and pillar, plus a one-page value-hypothesis template (auth uplift, fraud, cost, APM coverage, payouts).
A7: P1 | B7: Build | C7: ★ Explore Call Certification | D7: Practice (Days 31–60) | E7: 9 | F7: Pod lead + Enablement | H7: Not started | J7: See the certification rubric.
A8: P1 | B8: Build | C8: Day 60 review: pipeline, activity & ramp check | D8: Practice (Days 31–60) | E8: 9 | F8: Line manager | H8: Not started | J8: A structured 1:1 on pipeline created, meetings booked and cert results, with the next 30-day plan.
A9: P1 | B9: Build | C9: Storyline workshop: building a Checkout pitch deck | D9: Perform (Days 61–90) | E9: 13 | F9: Enablement + Product Marketing | H9: Not started | J9: Insight → value → proof → plan, using the Great Decks library (GM, 1800 Contacts, Flutter RFP, Caesars).
A10: P1 | B10: Build | C10: Business case lab: quantify the value | D10: Perform (Days 61–90) | E10: 13 | F10: Solutions Engineering + Deal Management | H10: Not started | J10: Turn the Day 60 value hypothesis into numbers using the pricing model and cost-analysis examples.
A11: P1 | B11: Build | C11: Deck peer review & dry run | D11: Perform (Days 61–90) | E11: 13 | F11: Buddy + pod | H11: Not started
A12: P1 | B12: Build | C12: ★ Pitch Deck Certification | D12: Perform (Days 61–90) | E12: 13 | F12: Panel: pod lead, SE, Enablement, guest leader | H12: Not started | J12: See the certification rubric.
A13: P1 | B13: Build | C13: Day 90 review & graduation to everboarding | D13: Perform (Days 61–90) | E13: 13 | F13: Line manager + Enablement | H13: Not started | J13: Ramp review against quota trajectory, certifications logged, and an individual development plan for Days 91–180.
A14: P1 | B14: Build | C14: Yearly recertification: Explore & Pitch | D14: Everboard (Day 90+) | E14: 14 | F14: Enablement | H14: Not started | J14: Keeps the bar consistent for tenured AEs (charter pillar 1: recertification rate).
A15: P1 | B15: Refresh | C15: Day 30 Checkpoint: elevator pitch + five-pillar knowledge check | D15: Learn (Days 15–30) | E15: 4 | F15: Line manager + Enablement | H15: Not started | J15: Combine today's elevator-pitch reviews and pillar Kahoots into one recorded gate.
A16: P2 | B16: Build | C16: Welcome pack, 90-day plan & personal tracker issued | D16: Pre-board (Before Day 1) | E16: 0 | F16: Enablement | H16: Not started | J16: Send the personal tracker (Karlie Chen format) and this 90-day map before Day 1 so the new hire arrives knowing the path.
A17: P2 | B17: Build | C17: Voice of the customer: Head of Payments panel | D17: Practice (Days 31–60) | E17: 7 | F17: Jaime Yeager / Jim Cho | H17: Not started | J17: Planned in both SME trackers but never scheduled. Heads of Payments share what resonated in outreach and what didn't.
A18: P2 | B18: Build | C18: Top-rep Q&A, every two weeks | D18: Practice (Days 31–60) | E18: 7 | F18: Sam Boukhiam / Louis Taupin | H18: Not started | J18: Planned to 'start in Month 2' but never started. Sam's notes in the Q4 plan are the starting agenda.
A19: P2 | B19: Build | C19: Payment performance metrics that matter (auth rates, declines, tokens, cost) | D19: Practice (Days 31–60) | E19: 8 | F19: Solutions Engineering + Product | H19: Not started | J19: The numbers an AE has to quantify in discovery. Builds on the Decline Code and PPA cheat sheets.
A20: P2 | B20: Build | C20: Pricing guidance & take rate | D20: Perform (Days 61–90) | E20: 10 | F20: Jim Cho + Francesco Falcone | H20: Not started | J20: Listed in the Q3 SME tracker but never scheduled. Covers guardrails, approvals and how to talk about price.
A21: P2 | B21: Build | C21: Payments economics: interchange++, fee & cost analysis | D21: Perform (Days 61–90) | E21: 11 | F21: Deal Management + Solutions Engineering | H21: Not started | J21: The resources exist (Gopuff and Rhino + Jetty cost analyses, L2/L3 interchange) and are tagged 'cover later', but there's no session.
A22: P2 | B22: Build | C22: Trade, deal structure & negotiation case studies | D22: Perform (Days 61–90) | E22: 11 | F22: Pod lead (TBD) | H22: Not started | J22: Negotiation, getting pricing approved, and minimum billing. The owner is still TBD in the SME tracker.
A23: P2 | B23: Refresh | C23: Tool access pre-provisioned (Salesforce, Clari, Apollo, LinkedIn Sales Nav, Highspot, Glean) | D23: Pre-board (Before Day 1) | E23: 0 | F23: Enablement + IT | H23: Not started | J23: Today this takes a Day 1 session. Request access at offer-accept so Day 1 can go to people and context.
... A35: P2 | B35: Refresh | C35: MBO, quota mechanics & your path to quota | D35: Perform (Days 61–90) | E35: 12 | F35: Francesco Falcone + Jim Cho | H35: Not started | J35: Reschedule to 60 minutes with Jim, and invite newer hires.

Sheet Explore Call Cert
A1: Explore Call Certification
A2: When | B2: Day 60 (Week 9)
A3: Format | B3: A 30-minute live, simulated Explore call. The assessor plays a scripted payments persona (e.g. Head of Payments at a mid-market subscription merchant). Recorded in Clari.
A4: Assessors | B4: Pod lead + Enablement (calibrated on the same rubric)
A5: Pass mark | B5: ≥ 80% overall (28/35) and no section below 3/5. One retake within 10 working days, with coaching.
A7: AE name
A8: Assessor
A9: Date
A11: Section | B11: What good looks like | C11: Score (1–5) | D11: Evidence / coaching notes
A12: Pre-call research & hypothesis | B12: Knows the merchant's model, footprint, likely PSP set-up and a starting hypothesis
A13: Opening & upfront contract | B13: Clear agenda, time check and agreed outcome for the call
A14: DEPTH questioning funnel | B14: Moves from broad to specific, with open questions and no early pitching
A15: Payments pain quantified | B15: Uncovers and sizes at least one pain: auth rate, fraud, cost, APMs or payouts
A16: Pillar mapping | B16: Links the pains to the right Checkout pillar and capability
A17: Listening & summarising | B17: Listens far more than talks, and plays the summary back accurately
A18: Committed next step | B18: A dated next step with the right stakeholders
A20: Total | C20: =SUM(C12:C18) | D20: out of 35
A21: Result | C21: =IF(COUNT(C12:C18)<7,"Incomplete",IF(AND(SUM(C12:C18)>=35*0.8,MIN(C12:C18)>=3),"PASS","RETAKE"))

Sheet Pitch Deck Cert
A1: Pitch Deck Certification
A2: When | B2: Day 90 (Week 13)
A3: Format | B3: A tailored deck for a real territory account: a 20-minute presentation plus 10 minutes of panel Q&A, with the panel playing the buying committee.
A4: Assessors | B4: Pod lead, Solutions Engineer, Enablement, plus a guest leader
A5: Pass mark | B5: ≥ 80% overall (32/40) and no section below 3/5. Exemplary decks go into the Great Decks library.
A7: AE name
A8: Assessor
A9: Date
A11: Section | B11: What good looks like | C11: Score (1–5) | D11: Evidence / coaching notes
A12: Merchant insight | B12: Opens with the merchant's world and priorities, not ours
A13: Value narrative | B13: Story connects their goals to Checkout pillars with clear outcomes
A14: Business case | B14: Quantified value (auth uplift, cost, fraud, ops) using their data
A15: Proof | B15: Relevant case studies, references or NPS evidence for the vertical
A16: Competitive differentiation | B16: Positions against the incumbent without disparaging them
A17: Pricing narrative | B17: Commercials framed within guidance, linked to value
A18: Mutual action plan | B18: Clear path to signature, integration and go-live
A19: Executive presence & Q&A | B19: Confident, concise, handles objections calmly
A21: Total | C21: =SUM(C12:C19) | D21: out of 40
A22: Result | C22: =IF(COUNT(C12:C19)<8,"Incomplete",IF(AND(SUM(C12:C19)>=40*0.8,MIN(C12:C19)>=3),"PASS","RETAKE"))

Sheet New Hire Tracker
A1: AE Onboarding Tracker: make a copy for each new hire
F2: Progress | G2: =IFERROR(COUNTIF(F9:F87,TRUE)/COUNTA(C9:C87),0)
A3: Name: | D3: Region:
A4: Job title: | D4: Line manager:
A5: Start date: | D5: Enablement manager:
A6: Buddy: | D6: Cohort:
A8: Week | B8: Target date | C8: Session | D8: Format | E8: Owner | F8: Complete? | G8: My notes
A9: Pre-board | B9: =IF($B$5="","",$B$5-3) | C9: Welcome pack, 90-day plan & personal tracker issued | D9: Self-paced | E9: Enablement | F9: FALSE
A10: Pre-board | B10: =IF($B$5="","",$B$5-3) | C10: Tool access pre-provisioned (Salesforce, Clari, Apollo, LinkedIn Sales Nav, Highspot, Glean) | D10: Self-paced | E10: Enablement + IT | F10: FALSE
A11: Pre-board | B11: =IF($B$5="","",$B$5-3) | C11: Buddy assigned + manager welcome call | D11: Live | E11: Line manager | F11: FALSE
A12: Week 1 | B12: =IF($B$5="","",$B$5+4) | C12: IT, People & Benefits inductions | D12: Live | E12: People Team | F12: FALSE
A13: Week 1 | B13: =IF($B$5="","",$B$5+4) | C13: Your onboarding plan: the 30/60/90 kickoff | D13: Live | E13: Enablement | F13: FALSE
A14: Week 1 | B14: =IF($B$5="","",$B$5+4) | C14: Intro to Checkout's Revenue Org (Global + NORAM) | D14: Live | E14: Michel Tornabene | F14: FALSE
A15: Week 1 | B15: =IF($B$5="","",$B$5+4) | C15: Mandatory compliance training (Nova) | D15: Self-paced | E15: New hire | F15: FALSE
A16: Week 1 | B16: =IF($B$5="","",$B$5+4) | C16: Payments at Checkout in 60 minutes | D16: Live | E16: Enablement + Solutions Engineering | F16: FALSE
A17: Week 1 | B17: =IF($B$5="","",$B$5+4) | C17: Sales Tools & Chrome Extensions | D17: Live | E17: J.J. Henry | F17: FALSE
A18: Week 1 | B18: =IF($B$5="","",$B$5+4) | C18: Finding answers: Highspot, Confluence & Glean | D18: Live | E18: Enablement | F18: FALSE
A19: Week 1 | B19: =IF($B$5="","",$B$5+4) | C19: Office hours with the NORAM GM | D19: Live | E19: Zack Levine | F19: FALSE
A20: Week 1 | B20: =IF($B$5="","",$B$5+4) | C20: RevWay 0–1: Intro to Revenue Way & Buyer Psychology | D20: Self-paced | E20: Self-directed | F20: FALSE
A21: Week 1 | B21: =IF($B$5="","",$B$5+4) | C21: Meet your pod + buddy coffee | D21: Practice | E21: Pod leader | F21: FALSE
A22: Week 2 | B22: =IF($B$5="","",$B$5+11) | C22: Buyer personas in payments (Head of Payments, CFO, CPO, Eng) | D22: Live | E22: J.J. Henry | F22: FALSE
A23: Week 2 | B23: =IF($B$5="","",$B$5+11) | C23: Competitive Landscape | D23: Live | E23: Michel Tornabene | F23: FALSE
A24: Week 2 | B24: =IF($B$5="","",$B$5+11) | C24: Territory planning (STP), Rules of Engagement & Incentive Ratings | D24: Live | E24: Francesco Falcone | F24: FALSE
A25: Week 2 | B25: =IF($B$5="","",$B$5+11) | C25: Salesforce, Clari & pipeline hygiene | D25: Live | E25: Francesco Falcone | F25: FALSE
A26: Week 2 | B26: =IF($B$5="","",$B$5+11) | C26: AI in Commercial | D26: Live | E26: Molly McKenna | F26: FALSE
A27: Week 2 | B27: =IF($B$5="","",$B$5+11) | C27: Meet the team: Sales, AM, Financial Partnerships, Partnerships, SE, RevOps | D27: Live | E27: Team leads | F27: FALSE
A28: Week 2 | B28: =IF($B$5="","",$B$5+11) | C28: Payments Academy: Foundations modules 1–5 | D28: Self-paced | E28: Self-directed | F28: FALSE
A29: Week 2 | B29: =IF($B$5="","",$B$5+11) | C29: RevWay 2–3: DEPTH Selling & Managing Pipeline | D29: Self-paced | E29: Self-directed | F29: FALSE
A30: Week 2 | B30: =IF($B$5="","",$B$5+11) | C30: Friday knowledge check (Kahoot, pod leads join), runs weekly | D30: Practice | E30: Enablement + pod leads | F30: FALSE
A31: Week 3 | B31: =IF($B$5="","",$B$5+18) | C31: Payments Academy: Foundations 6–10 + live debrief | D31: Self-paced | E31: Enablement | F31: FALSE
A32: Week 3 | B32: =IF($B$5="","",$B$5+18) | C32: Product Foundations: Connect & Move | D32: Self-paced | E32: Self-directed | F32: FALSE
A33: Week 3 | B33: =IF($B$5="","",$B$5+18) | C33: Pillars in live deals: Connect & Move (30 min each) | D33: Live | E33: Pod leads | F33: FALSE
A34: Week 3 | B34: =IF($B$5="","",$B$5+18) | C34: International Outlook: acquiring set-ups & cross-border | D34: Live | E34: Michel Tornabene | F34: FALSE
A35: Week 3 | B35: =IF($B$5="","",$B$5+18) | C35: Commercial Risk | D35: Live | E35: Michel Tornabene | F35: FALSE
A36: Week 3 | B36: =IF($B$5="","",$B$5+18) | C36: Intro to NORAM verticals & where we win | D36: Live | E36: Francesco Falcone | F36: FALSE
A37: Week 3 | B37: =IF($B$5="","",$B$5+18) | C37: Weekly call-review hour begins (Clari gametapes) | D37: Practice | E37: Jim Cho + Francesco Falcone | F37: FALSE
A38: Week 3 | B38: =IF($B$5="","",$B$5+18) | C38: Outreach lab: openers, email personalisation & gatekeepers | D38: Live | E38: J.J. Henry | F38: FALSE
A39: Week 4 | B39: =IF($B$5="","",$B$5+25) | C39: Product Foundations: Protect, Boost & Manage | D39: Self-paced | E39: Self-directed | F39: FALSE
A40: Week 4 | B40: =IF($B$5="","",$B$5+25) | C40: Pillars in live deals: Protect, Boost & Manage | D40: Live | E40: Pod leads | F40: FALSE
A41: Week 4 | B41: =IF($B$5="","",$B$5+25) | C41: Payment Performance AMA (Boost) | D41: Live | E41: Daniel Linder | F41: FALSE
...

Sheet Who to Meet
A1: Aim to finish within your first month. Adapted from the NY Sales Class repository and Karlie Chen's tracker; update names per cohort.
A3: Priority | B3: Name | C3: Why | D3: Met?
A4: P0 | B4: Line manager & buddy | C4: Your manager and day-to-day guide | D4: FALSE
A5: P0 | B5: Jim Cho | C5: VP Sales | D5: FALSE
A6: P1 | B6: Michel Tornabene | C6: Revenue Enablement | D6: FALSE
A7: P1 | B7: Zack Levine | C7: NORAM GM | D7: FALSE
A8: P1 | B8: Faith Bergman | C8: Deal Management lead | D8: FALSE
A9: P1 | B9: Rithvik Nair | C9: Your Deal Management contact | D9: FALSE
A10: P1 | B10: Sandra Suen | C10: BDR lead + RevOps strategy | D10: FALSE
A11: P1 | B11: Jarett Israel + team | C11: Underwriting | D11: FALSE
A12: P1 | B12: Jaime Yeager / Louis Taupin / Luke Brauer | C12: Pod leaders (ATL / SF / NY) | D12: FALSE
A13: P1 | B13: Matt Baum, Mike O'Connor & Ezra Cohen | C13: Financial Partnerships | D13: FALSE
A14: P1 | B14: Cyril Chemla | C14: Strategic Accounts Team | D14: FALSE
A15: P2 | B15: Michael Taylor | C15: TAM & SE lead | D15: FALSE
... A21: P3 | B21: Sam Boukhiam | C21: Top rep: tips & tricks | D21: FALSE
